Workbook
Name Validation_004b65848935b9e1ea176accdf8cebf7d7029af2629c4de75630ab35c71de4d8_product_attr_measurement_unit_seat_height: ReferenceData!$R$2:$R$2
Name Validation_034cc2e2142336c3f3bfac769ac755443f3d6a6890a9f0925b3b209c653301a0_product_attr_measurement_unit_package10_weight: ReferenceData!$AK$2:$AK$3
Name Validation_04e80df5cfe830552f34fddeda4036f17d4d208514dc6275e59139ab0abc6e22_product_attr_sofa_type: ReferenceData!$CE$2:$CE$5
Name Validation_073d2eb236ab7ddf49de1eb396004a4aee02632b32a507d43532114a3edb6b87_product_attr_measurement_unit_width: ReferenceData!$G$2:$G$2
Name Validation_081c0b5c08f42c382055f4180ed8d7d86182f3f83c79c4f165c9ff556d693424_product_attr_production: ReferenceData!$BD$2:$BD$3
Name Validation_0926fa9e6fbc6e480b2fd4d6032b23daf00b3ea8e315d11ec9a9c3f2af385135_product_attr_energy: ReferenceData!$AT$2:$AT$6
Name Validation_0b385e520545f4158f2262322b3f3db446eaff3b703348005ee353787e8601a8_product_attr_power_measurement_unit: ReferenceData!$S$2:$S$3
Name Validation_0db360015f4b36b8605332b1d2529fa7e65674f082f3fed33104b65851651672_product_attr_sofa_corner: ReferenceData!$BJ$2:$BJ$4
Name Validation_107488bc1a3a8fbcb9219fd28c1dba94cd3082529e0255cfbe09298f30cabd29_product_attr_measurement_unit_capacity: ReferenceData!$BW$2:$BW$4
Name Validation_15f0d09dfb358b3f11f461549215d1fea73b3df99b6f6db0afb3eef26342cb09_product_attr_measurement_unit_package5_weight: ReferenceData!$W$2:$W$3
Name Validation_186140fed797e97033dd68e3f039e4784a84bca9b288ef9e21aaffe4b45d2ae1_product_attr_scent: ReferenceData!$BV$2:$BV$3
Name Validation_18feb6fd7dc73dece159e4acb5b60dfcbe61dce7706daaf44521276fe91c5c25_product_attr_hanger_model: ReferenceData!$BQ$2:$BQ$11
Name Validation_19b229d00d671648c3466340d16fc940d4dfac4ad229b903d3a2f14cef42409d_product_attr_measurement_unit_seat_width: ReferenceData!$T$2:$T$2
Name Validation_261ae4c40bdcb680387c70d5475f39b88948224a7a7a44bb067ee63009f2d2ca_product_attr_portion: ReferenceData!$CC$2:$CC$3
Name Validation_27dbd16c9733711f7bdbbc94eb77be1e2dce4ed5e023b96b222e2bdc0ee3d7d3_product_attr_measurement_unit_package4_weight: ReferenceData!$AJ$2:$AJ$3
Name Validation_27f7e932441c45390790396bf14a9ec4b117841f8f75340d464bc667390fa086_product_attr_ideal_for: ReferenceData!$AY$2:$AY$7
Name Validation_2d4ef00828481e6edbc83fcc6197865f37020fef99ff496cce1ddb89a8652c5c_product_attr_table_model: ReferenceData!$CG$2:$CG$2
Name Validation_2e62d2d04449b29259f350761525dbec7e04f759d68a47d3846c73f9696d7e05_product_attr_lamp_model: ReferenceData!$AU$2:$AU$3
Name Validation_2f85fcf368c29e61b3d0429a91df69230f1a128e3d979c9d42c0b75aa0d238a1_product_attr_is_product_recyclable: ReferenceData!$O$2:$O$3
Name Validation_328b9876965cf8161081ebec49b5d122a92884208edd7fb6cdb1dbf3c416e0d2_product_attr_measurement_unit_height: ReferenceData!$E$2:$E$2
Name Validation_34ed3e0c2a6c1ffa9f43b3c8d6cad6ad0a6f276d09f7b0ac0d96276e125043b5_product_attr_mirror_model: ReferenceData!$BB$2:$BB$13
Name Validation_39674193e4e465e1d11369002294284c6f0c538a7e9d53c8b05d0c3fd10540b4_product_attr_characteristic: ReferenceData!$Y$2:$Y$18
Name Validation_3a5607bc90c739387de9081c3fb5eb706e4f334b2887737dd354fee3a757915c_product_attr_style: ReferenceData!$K$2:$K$8
Name Validation_3c68c6523dd07bff0c29e856adc1b72966fc7aff2d2a3a2f4237ee295d621097_product_attr_product_finish: ReferenceData!$P$2:$P$12
Name Validation_3fadda4850edf058a64944408c88b40e6734c6c7c4293d3a02d7dabc9513376b_product_attr_measurement_unit_package2_weight: ReferenceData!$AF$2:$AF$3
Name Validation_4177f839b50cba64238187a248a918fb49bf545fdf70144d98998ea0cc65d469_product_attr_vase_model: ReferenceData!$BX$2:$BX$7
Name Validation_4876bc139665ccb9242cabf44652c979cf63868556a6b04614caf02fe9f895fe_product_attr_measurement_unit_package6_weight: ReferenceData!$AA$2:$AA$3
Name Validation_4c1c4731a9ae52779239b82b7d4b67745983fe30fb0c5c28aee7e339182d5140_product_attr_bulb_base_type: ReferenceData!$Q$2:$Q$17
Name Validation_523e92f02b0e70d27f6ac509a3a844aa39a0936b8cda01d0a8a14a989d7cf056_product_attr_washable_care: ReferenceData!$L$2:$L$7
Name Validation_53fdf102506278c56b96dadd6577bfeb8e9fdd65b086f2f1d1e419a7ec29dae9_product_attr_number_battery: ReferenceData!$BI$2:$BI$11
Name Validation_54f7557410ebf02ef20a0b9f7ac87e668b58ed97df9fa9cd94583975b2b99c11_product_attr_bathroom_accessory_model: ReferenceData!$BL$2:$BL$5
Name Validation_575b43b55067814554be1c07d11ef4154a79b34daa1c56fc81fb45165d2410e5_product_attr_does_product_contain_dangerous_substances: ReferenceData!$M$2:$M$3
Name Validation_57cf927f889b85715ce85accc3e2d5994dc11ba39dcf549b2d13791dc1fee871_product_attr_pattern: ReferenceData!$X$2:$X$3
Name Validation_592fd27c4bdf7bc45d2125c9423a2da20eeaea8b22abe07803283385719d2c51_product_attr_furniture_type: ReferenceData!$BY$2:$BY$5
Name Validation_5d225a507a9c87f4759308b2798de1b7c468a8289e4b99578d2389c7c71d6241_product_attr_nb_doors: ReferenceData!$BU$2:$BU$6
Name Validation_64c0e6b5337bdd1310d888c16566d4354da69ff9ff0dc9c3bee6f1af4292cb7b_product_attr_turn_on_system: ReferenceData!$AO$2:$AO$5
Name Validation_6f183be25cad241f19a07e36e6ac377e646cdea25e3bd3a5e8108f074c720bf7_product_attr_accessory_included: ReferenceData!$CF$2:$CF$13
Name Validation_6f3363ce38783950ca8b8106e9ddb5d97b797e9d7c6f6cc0568b7700bf38dc01_product_attr_bottom_typ: ReferenceData!$AV$2:$AV$3
Name Validation_6f7b2a51e857050b0248f722d466e5274d567637db9024d22bc4c7625b0b1022_product_attr_brand: ReferenceData!$B$2:$B$3653
Name Validation_75b06dc2c7e899e739470de5f2c35722fd48e593ea0b9a3bc70dff2e76f2ee46_product_attr_measurement_unit_diameter: ReferenceData!$H$2:$H$2
Name Validation_774a52a94dadf8305d05db5133e1fcebd0c78791f67871b7e7fcce0b5a8c81c8_product_attr_battery_type: ReferenceData!$BH$2:$BH$7
Name Validation_89abe726d61831fe243275e73176ec0994d3495661e7e94597aff3db182e046b_product_attr_measurement_unit_package7_weight: ReferenceData!$AE$2:$AE$3
Name Validation_8b83d2f1d8286bf1a90e40b7e55ba20d0f92ebcf22f86cb38416aa951ec41d20_product_attr_chair_model: ReferenceData!$AS$2:$AS$4
Name Validation_8f523cd390ff91edf9fbe78aa24bd642aa342ee36309a2b7f21a376d69a24bb6_product_attr_measurement_unit_seat_depth: ReferenceData!$U$2:$U$2
Name Validation_8ff177e64dd98071eeb68fea12c970a1a429c04e29e874705f4b410c7305af2b_product_attr_made_in: ReferenceData!$I$2:$I$205
Name Validation_92de071aebc97e378ae9b7a302e90b019fd10d7321796809000f5dbff9f2dcef_product_attr_modular_type: ReferenceData!$AQ$2:$AQ$8
Name Validation_942c733d78b217d5af2f6cd4432a3564b3a20e4e268be845b8ea005fc8206dda_product_attr_theme: ReferenceData!$AM$2:$AM$17
Name Validation_9798d01db3854a31923e0925f00d99bb93e2dad39b80d39a18a1c0fd4ddb6214_product_attr_specific_treatment: ReferenceData!$Z$2:$Z$7
Name Validation_98a0c32f3932767727ea6c27f3a11e9002c121df7fae47a0406302d074698436_product_attr_measurement_unit_length: ReferenceData!$F$2:$F$2
Name Validation_99bc66488194f93ea9cc9f9c9faf4d89ed0871f91475debb51c1d3542addf02d_product_attr_measurement_unit_package8_weight: ReferenceData!$AG$2:$AG$3
Name Validation_9ae9b620ca27a6948276d84e5df9d633fa516ccbf63b793c2081080eb38eeac8_product_attr_category: ReferenceData!$A$2:$A$111
Name Validation_a01ea7592c0c0e5a9dcf312b7318c5a576cdab41a411b83a5552e14bf5499ef5_product_attr_measurement_unit_package3_weight: ReferenceData!$AH$2:$AH$3
Name Validation_a044674cea1ebe2def514978765fdb7c9f18e00a6dc52e5834730482ae026de0_product_attr_padding: ReferenceData!$AW$2:$AW$5
Name Validation_a3d65393ac3942743b9de113f6a9f1abe7769d29052e9f6ea978c93fe63774a3_product_attr_pose: ReferenceData!$BF$2:$BF$6
Name Validation_a59ef51f4b287e47a443018e6be0c9a8ed8c835fca6ee0634e87b786cd1c9d27_product_attr_lounge_chair_model: ReferenceData!$CD$2:$CD$5
Name Validation_a5c2f46a5e679273bca1d36811a8d63334f2d329b5274de7006634536d28c10f_product_attr_nb_seats: ReferenceData!$BE$2:$BE$11
Name Validation_acef16430d35b9704e8b261bb996c5c85aa7ab14c71c30bae653ef88bef191a0_product_attr_baking_accesory: ReferenceData!$BP$2:$BP$11
Name Validation_b0e6a72a59d74a730cb09a4fc97bbe94eac35697ad7c9d82aa9aabc7e52be8b6_product_attr_energy_source: ReferenceData!$AN$2:$AN$7
Name Validation_bdee35a5463e4c34ee3a6d9a0f69bc6fb5083745b974129b3e1e71a6f2f99a72_product_attr_measurement_unit_armrest_width: ReferenceData!$V$2:$V$2
Name Validation_c3364daee02ad55a75b442bed8d1ded8b18246e611257bfa56d2e57ef025deef_product_attr_quality_bed: ReferenceData!$AR$2:$AR$3

Sheet Data
A1: Category | B1: Reference | D1: Product title | E1: Product title | F1: Product title | G1: Product title | H1: Ean Code | I1: Variant Code Group | J1: Brand | K1: Collection | L1: Description | M1: Description | N1: Description | O1: Description | P1: Color | Q1: Main Material | R1: Material Description | S1: Material Description | T1: Material Description | U1: Material Description | V1: Marketing Color | W1: Marketing Color | X1: Marketing Color | Y1: Marketing Color | Z1: Height | AA1: Measurement Unit Height | AB1: Length | AC1: Measurement Unit Length | AD1: Width | AE1: Measurement Unit Width | AF1: Diameter | AG1: Measurement Unit Diameter | AH1: Structure Material | AI1: Structure Material | AJ1: Structure Material | AK1: Structure Material | AL1: Wood Essence | AM1: Wood Essence | AN1: Wood Essence | AO1: Wood Essence | AP1: Wood Origin | AQ1: Wood Origin | AR1: Wood Origin | AS1: Wood Origin | AT1: Made In | AU1: Guarantee | AV1: Guarantee | AW1: Guarantee | AX1: Guarantee | AY1: Eco Responsible Label | AZ1: Style | BA1: Standards | BB1: Standards | BC1: Standards | BD1: Standards | BE1: Washable Care | BF1: Vidéo | BG1: Media 1 | BH1: Media 5 | BI1: Media 6 | BJ1: Media 7 | BK1: Media 8 | BL1: Media 9 | BM1: Media 10 | BN1: Pays principal de teinture ou impression du produit | BO1: Pays principal de confection du produit | BP1: Pays principal de tissage du produit | BQ1: Le produit contient au moins __value__ milligrammes de métaux précieux | BR1: Le produit contient au moins __value__ milligrammes de terres rares | BS1: Contenu minimum en matières recyclées dans l'emballage | BT1: Contenu minimum en matières recyclées dans le produit | BU1: Contient une substance extrêmement préoccupante | BV1: Contenu minimum en matières d'origine renouvelable dans le produit | BW1: Rejette des microfibres plastiques dans l'environnement lors du lavage | BX1: Présence de substances dangereuses | BY1: Emballage majoritairement recyclable | BZ1: Produit majoritairement recyclable | CA1: Name, company name or registered trademark of the manufacturer if in the EU, or of the responsible person in the EU | CB1: Postal address of the manufacturer if in the EU, or of the responsible person in the EU | CC1: Electronic contact details of the manufacturer if in the EU, or of the responsible person in the EU | CD1: Product size | CE1: Product Finish | CF1: Seat Height | CG1: Media 2 | CH1: Bulb Base Type | CI1: Measurement Unit Seat Height | CJ1: Media 3 | CK1: Watt Power | CL1: Seat Width | CM1: Media 4 | CN1: Power Measurement Unit | CO1: Measurement Unit Seat Width | CP1: Protection Index | CQ1: Seat Depth | CR1: Protection Index | CS1: Measurement Unit Seat Depth | CT1: Protection Index | CU1: Armrest Width | CV1: Protection Index | CW1: Measurement Unit Armrest Width | CX1: Seat Cushion Padding | CY1: Back Cushion Padding | CZ1: Armrest Cushion Padding | DA1: Package5 Weight | DB1: Seat Suspensions | DC1: Measurement Unit Package5 Weight | DD1: Pattern | DE1: Package5 Size | DF1: Characteristic | DG1: Package6 Weight | DH1: Specific Treatment | DI1: Measurement Unit Package6 Weight | DJ1: Assembling | DK1: Package6 Size | DL1: Nb Packages | DM1: Package7 Weight | DN1: Package1 Weight | DO1: Measurement Unit Package1 Weight | DP1: Measurement Unit Package7 Weight | DQ1: Package1 Size | DR1: Package7 Size | DS1: Package8 Weight | DT1: Package2 Weight | DU1: Measurement Unit Package2 Weight | DV1: Measurement Unit Package8 Weight | DW1: Package2 Size | DX1: Package8 Size | DY1: Package3 Weight | DZ1: Package9 Weight | EA1: Measurement Unit Package3 Weight | EB1: Measurement Unit Package9 Weight | EC1: Package3 Size | ED1: Package9 Size | EE1: Package4 Weight | EF1: Package10 Weight | EG1: Measurement Unit Package4 Weight | EH1: Measurement Unit Package10 Weight | EI1: Package4 Size | EJ1: Package10 Size | EK1: Armrest Cushion Padding | EL1: Seat Cushion Padding | EM1: Back Cushion Padding | EN1: Seat Suspensions | EO1: Armrest Cushion Padding | EP1: Back Cushion Padding | EQ1: Seat Cushion Padding | ER1: Seat Suspensions | ES1: Armrest Cushion Padding | ET1: Back Cushion Padding | EU1: Seat Cushion Padding | EV1: Seat Suspensions | EW1: Armchair Model | EX1: Theme | EY1: Energy Source | EZ1: Turn On System | FA1: Form | FB1: Modular Type | FC1: Quality Bed | FD1: Chair Model | FE1: Energy | FF1: Lamp model | FG1: Specific Bed Size | FH1: Bottom Typ | FI1: Padding | FJ1: Storage | FK1: Ideal for | FL1: Compatible With | FM1: Floor Lamp Model | FN1: Bulb Number | FO1: Mirror Model | FP1: Function | FQ1: Production | FR1: Nb Seats | FS1: Pose | FT1: Armrest | FU1: Compatible With | FV1: Battery | FW1: Compatible With | FX1: Nb Battery | FY1: Compatible With | FZ1: Sofa Corner | GA1: Food Type | GB1: Bathroom Accessory Model | GC1: Bed Size | GD1: Burning Time | GE1: Cup Model | GF1: Furniture Model | GG1: Baking Accesory | GH1: Capacity | GI1: Hanger Model | GJ1: Plate Model | GK1: Pan Model | GL1: Baking Sheet Type | GM1: Nb Doors | GN1: Perfume | GO1: Measurement Unit Capacity | GP1: Vase model | GQ1: Furniture Type | GR1: Nb Drawer | GS1: Carpet Model | GT1: Handle Type | GU1: Portion | GV1: Type of fragrance | GW1: Weaving Technical | GX1: Lounge Chair Model | GY1: Sofa Type | GZ1: Accessory Included | HA1: Burning Time | HB1: Table Model | HC1: Wick Thickness | HD1: Type of fragrance | HE1: Weaving Technical | HF1: Burning Time | HG1: Weaving Technical | HH1: Type of fragrance | HI1: Weaving Technical | HJ1: Burning Time | HK1: Type of fragrance
A2: attr_category | B2: attr_reference | D2: attr_name | E2: attr_name_es | F2: attr_name_it | G2: attr_name_de | H2: attr_ean | I2: attr_variant_code_group | J2: attr_brand | K2: attr_collection | L2: attr_description | M2: attr_description_it | N2: attr_description_es | O2: attr_description_de | P2: attr_color | Q2: attr_material | R2: attr_material_description | S2: attr_material_description_es | T2: attr_material_description_de | U2: attr_material_description_it | V2: attr_marketing_color | W2: attr_marketing_color_es | X2: attr_marketing_color_it | Y2: attr_marketing_color_de | Z2: attr_height | AA2: attr_measurement_unit_height | AB2: attr_length | AC2: attr_measurement_unit_length | AD2: attr_width | AE2: attr_measurement_unit_width | AF2: attr_diameter | AG2: attr_measurement_unit_diameter | AH2: attr_structure_material | AI2: attr_structure_material_es | AJ2: attr_structure_material_it | AK2: attr_structure_material_de | AL2: attr_wood_essence | AM2: attr_wood_essence_es | AN2: attr_wood_essence_it | AO2: attr_wood_essence_de | AP2: attr_wood_country_origin | AQ2: attr_wood_country_origin_es | AR2: attr_wood_country_origin_it | AS2: attr_wood_country_origin_de | AT2: attr_made_in | AU2: attr_guarantee | AV2: attr_guarantee_es | AW2: attr_guarantee_it | AX2: attr_guarantee_de | AY2: attr_eco_responsible_label | AZ2: attr_style | BA2: attr_standards | BB2: attr_standards_es | BC2: attr_standards_it | BD2: attr_standards_de | BE2: attr_washable_care | BF2: attr_video | BG2: attr_media_1 | BH2: attr_media_5 | BI2: attr_media_6 | BJ2: attr_media_7 | BK2: attr_media_8 | BL2: attr_media_9 | BM2: attr_media_10 | BN2: attr_country_of_transformation_dyeing_printing_label | BO2: attr_country_of_transformation_garment_label | BP2: attr_country_of_transformation_weaving_label | BQ2: attr_mass_of_precious_metals | BR2: attr_mass_of_rare_earths | BS2: attr_minimum_percentage_of_recycled_material_in_packaging | BT2: attr_minimum_percentage_of_recycled_material_in_product | BU2: attr_name_of_dangerous_substance | BV2: attr_percentage_of_renewable_material | BW2: attr_percentage_of_synthetic_fibres | BX2: attr_does_product_contain_dangerous_substances | BY2: attr_is_packaging_recyclable | BZ2: attr_is_product_recyclable | CA2: attr_ue_manufacturer_representative_name | CB2: attr_ue_manufacturer_representative_address | CC2: attr_ue_manufacturer_representative_email | CD2: attr_product_size | CE2: attr_product_finish | CF2: attr_seat_height | CG2: attr_media_2 | CH2: attr_bulb_base_type | CI2: attr_measurement_unit_seat_height | CJ2: attr_media_3 | CK2: attr_max_power | CL2: attr_seat_width | CM2: attr_media_4 | CN2: attr_power_measurement_unit | CO2: attr_measurement_unit_seat_width | CP2: attr_protection_index | CQ2: attr_seat_depth | CR2: attr_protection_index_es | CS2: attr_measurement_unit_seat_depth | CT2: attr_protection_index_it | CU2: attr_armrest_width | CV2: attr_protection_index_de | CW2: attr_measurement_unit_armrest_width | CX2: attr_seat_cushion_padding | CY2: attr_back_cushion_padding | CZ2: attr_armrest_cushion_padding | DA2: attr_package5_weight | DB2: attr_seat_suspensions | DC2: attr_measurement_unit_package5_weight | DD2: attr_pattern | DE2: attr_package5_size | DF2: attr_characteristic | DG2: attr_package6_weight | DH2: attr_specific_treatment | DI2: attr_measurement_unit_package6_weight | DJ2: attr_assembled | DK2: attr_package6_size | DL2: attr_nb_packages | DM2: attr_package7_weight | DN2: attr_package1_weight | DO2: attr_measurement_unit_package1_weight | DP2: attr_measurement_unit_package7_weight | DQ2: attr_package1_size | DR2: attr_package7_size | DS2: attr_package8_weight | DT2: attr_package2_weight | DU2: attr_measurement_unit_package2_weight | DV2: attr_measurement_unit_package8_weight | DW2: attr_package2_size | DX2: attr_package8_size | DY2: attr_package3_weight | DZ2: attr_package9_weight | EA2: attr_measurement_unit_package3_weight | EB2: attr_measurement_unit_package9_weight | EC2: attr_package3_size | ED2: attr_package9_size | EE2: attr_package4_weight | EF2: attr_package10_weight | EG2: attr_measurement_unit_package4_weight | EH2: attr_measurement_unit_package10_weight | EI2: attr_package4_size | EJ2: attr_package10_size | EK2: attr_armrest_cushion_padding_es | EL2: attr_seat_cushion_padding_es | EM2: attr_back_cushion_padding_es | EN2: attr_seat_suspensions_es | EO2: attr_armrest_cushion_padding_it | EP2: attr_back_cushion_padding_it | EQ2: attr_seat_cushion_padding_it | ER2: attr_seat_suspensions_it | ES2: attr_armrest_cushion_padding_de | ET2: attr_back_cushion_padding_de | EU2: attr_seat_cushion_padding_de | EV2: attr_seat_suspensions_de | EW2: attr_armchair_model | EX2: attr_theme | EY2: attr_energy_source | EZ2: attr_turn_on_system | FA2: attr_form | FB2: attr_modular_type | FC2: attr_quality_bed | FD2: attr_chair_model | FE2: attr_energy | FF2: attr_lamp_model | FG2: attr_specific_bed_size | FH2: attr_bottom_typ | FI2: attr_padding | FJ2: attr_storage | FK2: attr_ideal_for | FL2: attr_compatible_with | FM2: attr_floor_lamp_model | FN2: attr_number_bulbs | FO2: attr_mirror_model | FP2: attr_function | FQ2: attr_production | FR2: attr_nb_seats | FS2: attr_pose | FT2: attr_armrest | FU2: attr_compatible_with_es | FV2: attr_battery_type | FW2: attr_compatible_with_it | FX2: attr_number_battery | FY2: attr_compatible_with_de | FZ2: attr_sofa_corner | GA2: attr_food_type | GB2: attr_bathroom_accessory_model | GC2: attr_bed_size | GD2: attr_burning_time | GE2: attr_cup_model | GF2: attr_furniture_model | GG2: attr_baking_accesory | GH2: attr_product_capacity | GI2: attr_hanger_model | GJ2: attr_plate_model | GK2: attr_pan_model | GL2: attr_baking_sheet_type | GM2: attr_nb_doors | GN2: attr_scent | GO2: attr_measurement_unit_capacity | GP2: attr_vase_model | GQ2: attr_furniture_type | GR2: attr_nb_drawer | GS2: attr_carpet_model | GT2: attr_handle_type | GU2: attr_portion | GV2: attr_type_fragrance | GW2: attr_weaving_technical | GX2: attr_lounge_chair_model | GY2: attr_sofa_type | GZ2: attr_accessory_included | HA2: attr_burning_time_es | HB2: attr_table_model | HC2: attr_wick_thickness | HD2: attr_type_fragrance_es | HE2: attr_weaving_technical_es | HF2: attr_burning_time_it | HG2: attr_weaving_technical_it | HH2: attr_type_fragrance_it | HI2: attr_weaving_technical_de | HJ2: attr_burning_time_de | HK2: attr_type_fragrance_de
A3: Decoration/Rugs/Living room rugs | B3: AFCHU001_0298-290x197 | C3: =_xlfn.XLOOKUP(B3,Sheet1!A:A,Sheet1!A:A,) -> AFCHU001_0298-290x197 | H3: 6097312255277 | J3: Bazar Bizar | L3: <p><span>Le Tapis Afghan Tissé à la Main #0298 porte l’héritage des traditions afghanes séculaires, où motifs et textures dépassent la décoration pour devenir récit culturel. Sa base en laine ivoire douce est parcourue de fines lignes brunes, encadrée de tons plus profonds et terminée par des franges qui célèbrent son essence artisanale.<br><br>Mesurant 290 × 197 cm, il apporte équilibre et chaleur aux grands espaces, qu’il s’agisse d’un salon formel, d’une salle à manger ou d’un bureau. Les fibres de laine durables, travaillées à la main et souvent teintées avec des pigments naturels, assurent solidité au quotidien tout en offrant confort tactile et douceur sous les pieds.<br><br>Chaque tapis est une création singulière, avec des nuances et irrégularités de tissage révélant la main de l’artisan. Cette pièce est non seulement un textile fonctionnel mais aussi un patrimoine vivant, reconnu mondialement par des prix internationaux et transmis de génération en génération par les tisserands afghans.</span></p> | M3: <p><span>Il Tappeto Afgano Tessuto a Mano #0298 porta con sé il peso delle tradizioni tessili afghane secolari, dove motivi e texture sono più che decorazione: sono narrazione culturale. La sua base in lana avorio è segnata da sottili linee marroni, bordata da tonalità più scure e rifinita con frange che celebrano la sua essenza artigianale.<br><br>Con dimensioni di 290 × 197 cm, dona equilibrio e calore a spazi ampi, che si tratti di un soggiorno formale, di una sala da pranzo o di uno studio. Le fibre di lana resistenti, lavorate a mano e spesso colorate con pigmenti naturali, garantiscono solidità nell’uso quotidiano mantenendo comfort e morbidezza.<br><br>Ogni tappeto è una creazione singolare, con variazioni di tono e tessitura che rivelano la mano dell’artigiano. Questo pezzo non è solo un tessuto funzionale ma un patrimonio vivente, parte di una tradizione riconosciuta a livello internazionale e tramandata da generazioni di tessitori afghani.</span></p> | N3: <p><span>La Alfombra Afgana Tejida a Mano #0298 lleva consigo el peso de las tradiciones afganas ancestrales, donde los patrones y texturas son narración cultural más allá de la decoración. Su base de lana marfil suave está trazada con finas líneas marrones, enmarcada por tonos más profundos y acabada con flecos que celebran su esencia artesanal.<br><br>Con un tamaño de 290 × 197 cm, aporta equilibrio y calidez a amplios espacios, ya sea en un salón formal, un comedor o un estudio. Las fibras de lana duraderas, trabajadas a mano y teñidas a menudo con pigmentos naturales, garantizan resistencia para el uso diario y suavidad bajo los pies.<br><br>Cada alfombra es una creación única, con sutiles variaciones en el tejido y el tono que revelan la mano del artesano. Esta pieza no solo es un textil funcional sino también un patrimonio vivo, parte de una tradición reconocida mundialmente con premios internacionales y transmitida por generaciones de tejedores afganos.</span></p> | O3: <p><span>Der Handgewebte Afghanische Teppich #0298 trägt das Gewicht jahrhundertealter afghanischer Webtraditionen, in denen Muster und Texturen mehr als Dekoration sind – sie sind kulturelles Erzählen. Der weiche elfenbeinfarbene Wollgrund ist mit feinen braunen Linien durchzogen, von dunkleren Tönen eingefasst und mit Fransen versehen, die seine handwerkliche Essenz betonen.<br><br>Mit den Maßen 290 × 197 cm bringt er Balance und Wärme in großzügige Räume, sei es ein formales Wohnzimmer, ein Essbereich oder ein Arbeitszimmer. Strapazierfähige Wollfasern, von Hand verarbeitet und oft mit Naturfarben gefärbt, sorgen für Stärke im Alltag und bieten zugleich weichen Komfort.<br><br>Jeder Teppich ist ein Unikat, mit feinen Abweichungen in Gewebe und Farbton, die die Hand des Kunsthandwerkers sichtbar machen. Dieses Stück ist nicht nur funktionaler Textil, sondern auch lebendiges Erbe, Teil einer Tradition, die weltweit mit internationalen Preisen ausgezeichnet und von Generation zu Generation afghanischer Weber weitergegeben wird.</span></p> | P3: Beige | Q3: Wool | Z3: 1 | AA3: cm | AB3: 290 | AC3: cm | AD3: 197 | AE3: cm | AG3: cm | AT3: United Arab Emirates | BG3: https://bazarbizar.katanapim.com/content/images/thumbs/002/0028137_afchu001_0298-290x197.jpeg | CA3: Bazar Bizar | CB3: 2550 | CD3: 290 x 197 x 1 cm | CG3: https://bazarbizar.katanapim.com/content/images/thumbs/002/0024083_the-handwoven-afghan-rug-0298.jpeg | CJ3: https://bazarbizar.katanapim.com/content/images/thumbs/002/0024082_the-handwoven-afghan-rug-0298.jpeg | DD3: Without pattern | FA3: Rectangular | GS3: Oriental carpet | HC3: Short wick
A4: Storage accessories/Decorative storages/Baskets | B4: BA001B-M | C4: =_xlfn.XLOOKUP(B4,Sheet1!A:A,Sheet1!A:A,) -> BA001B-M | D4: Panier en bambou et perles noir 15x15x15cm | E4: Cesta de bambú y cuentas en negro 15x15x15 cm | F4: Cesto in bambù e perline nero 15x15x15 cm | G4: Korb aus Bambus und Perlen in schwarz, 15 x 15 x 15 cm | H4: 7438246078089 | I4: BA001 | J4: Bazar Bizar | K4: Beaded | L4: <p>Ces boîtes à offrandes joliment perlées sont entièrement fabriquées à la main par des artisans balinais avec amour et soin. À utiliser comme rangement ou simple élément décoratif, séparément ou ensemble, elles trouveront une place remarquable dans votre intérieur. Utilisées à Bali lors des cérémonies religieuses pour contenir les offrandes destinées aux dieux, elles ajouteront une touche d'authenticité et d'exotisme à votre décoration.</p> | M4: <p>Questi splendidi cestini d'offerta con perline sono interamente fatti a mano da artigiani balinesi con amore e cura. Perfetti come contenitori o come elementi decorativi, separati o insieme trovano posto nella vostra casa. Utilizzati a Bali per custodire le offerte agli dei, oggi arricchiscono l'arredo con autenticità ed esotismo.</p> | N4: <p>Estas cajas de ofrenda con abalorios están hechas completamente a mano por artesanos balineses con cuidado y dedicación. Puedes usarlas para guardar objetos o como elemento decorativo. Se emplean en Bali durante ceremonias religiosas para guardar ofrendas y ahora añadirán autenticidad y exotismo a tu hogar.</p> | O4: <p>Diese liebevoll mit Perlen verzierten Opferboxen werden von balinesischen Kunsthandwerkern handgefertigt. Ob als Aufbewahrung oder Dekoration, einzeln oder zusammen sind sie ein Blickfang in Ihrem Zuhause. In Bali dienen sie zur Aufbewahrung von Opfergaben für die Götter und bringen nun Authentizität und Exotik in Ihre Einrichtung.</p> | P4: Black | Q4: Bamboo | Z4: 15 | AA4: cm | AB4: 15 | AC4: cm | AD4: 15 | AE4: cm | AG4: cm | AT4: Indonesia | BG4: https://bazarbizar.katanapim.com/content/images/thumbs/002/0027694_ba001b-m.jpeg | CA4: Bazar Bizar | CB4: 2550 | CD4: 15 x 15 x 15 cm | CG4: https://bazarbizar.katanapim.com/content/images/thumbs/001/0019005_the-burned-bowl-black-s.jpeg | CJ4: https://bazarbizar.katanapim.com/content/images/thumbs/001/0019008_the-beaded-basket-black-s.jpeg | CM4: https://bazarbizar.katanapim.com/content/images/thumbs/001/0019007_the-beaded-basket-black-s.jpeg | FA4: Square | FQ4: Artisanal
A5: Storage accessories/Decorative storages/Baskets | B5: BA001B-SET3 | C5: =_xlfn.XLOOKUP(B5,Sheet1!A:A,Sheet1!A:A,) -> BA001B-SET3 | H5: 7438246089078 | J5: Bazar Bizar | L5: Ces boîtes à offrandes joliment perlées sont entièrement fabriquées à la main par des artisans balinais avec amour et soin. A utiliser comme rangement ou simple élément décoratif, séparément ou ensemble ces boîtes trouveront une place accrocheuse dans votre maison ! Elles sont utilisées à Bali lors des cérémonies religieuses pour contenir les offrandes aux dieux, transformées en objet décoratif ces boîtes ajouteront une touche d'authenticité et d'exotisme à votre décoration. | M5: Questi bellissimi cestini d'offerta di perline sono completamente fatte a mano da artigiani balinesi con amore e cura. Possono essere utilizzati per lo stoccaggio o semplicemente come elemento decorativo. Separatamente o insieme, questi cestini troveranno un posto accattivante nella vostra casa. Sono stati utilizzati a Bali durante le cerimonie religiose per contenere le offerte agli dei, e ora saranno un oggetto decorativo che aggiungerà un tocco di autenticità ed esotismo alla vostra decorazione. | N5: Estas cajas de ofrenda decoradas con hermosos abalorios, son hechas completamente a mano con mucho amor y cuidado por artesanos balineses. Puedes utilizarlas para almacenar cosas o simplemente como un bonito elemento decorativo. Se conocen por ser usadas en Bali para guardar ofrendas a los dioses durante ceremonias religiosas, y ahora han sido transformadas en un bonito objeto que añadirá un toque de autenticidad y exotismo a tu decoración. | O5: Diese wunderschön mit Perlen verzierten Opferboxen werden von balinesischen Kunsthandwerkern mit viel Liebe und Sorgfalt handgefertigt. Als Aufbewahrung oder einfaches Dekorationselement zu verwenden, einzeln oder zusammen werden diese Boxen einen auffälligen Platz in Ihrem Zuhause finden! Sie werden in Bali bei religiösen Zeremonien verwendet, um Opfergaben für die Götter aufzubewahren. In ein dekoratives Objekt verwandelt, werden diese Boxen Ihrer Dekoration einen Hauch von Authentizität und Exotik verleihen. | P5: Black | Q5: Bamboo | R5: Bambou - Perles | S5: Bambú - Cuentas | T5: Bamboo - Perlen | U5: Bambù - Perline | V5: Noir | W5: Negro | X5: Nero | Y5: Schwarz | Z5: 0 | AA5: cm | AB5: 12-15-20 | AC5: cm | AD5: 12-15-20 | AE5: cm | AG5: cm | AT5: Indonesia | AZ5: Sea side | BG5: https://bazarbizar.katanapim.com/content/images/thumbs/0009384_ba001b-set3.webp | BH5: https://bazarbizar.katanapim.com/content/images/thumbs/0009391_ba001b-set3_5.webp | CD5: 12-15-20cm x 12-15-20cm x 0cm | CG5: https://bazarbizar.katanapim.com/content/images/thumbs/0013994_the-burned-bowl-black-s.webp | CJ5: https://bazarbizar.katanapim.com/content/images/thumbs/0009385_ba001b-set3_100.webp | CM5: https://bazarbizar.katanapim.com/content/images/thumbs/0009386_ba001b-set3_101.webp | FA5: Other form | FQ5: Artisanal
A6: Storage accessories/Decorative storages/Baskets | B6: BA001W-SET3 | C6: =_xlfn.XLOOKUP(B6,Sheet1!A:A,Sheet1!A:A,) -> BA001W-SET3 | F6: Set di 3 cestini bianchi con perline | H6: 7438246089061 | J6: Bazar Bizar | M6: Questi bellissimi cestini d'offerta di perline sono completamente fatte a mano da artigiani balinesi con amore e cura. Possono essere utilizzati per lo stoccaggio o semplicemente come elemento decorativo. Separatamente o insieme, questi cestini troveranno un posto accattivante nella vostra casa. Sono stati utilizzati a Bali durante le cerimonie religiose per contenere le offerte agli dei, e ora saranno un oggetto decorativo che aggiungerà un tocco di autenticità ed esotismo alla vostra decorazione. | Z6: 15 | AA6: cm | AB6: 20 | AC6: cm | AD6: 20 | AE6: cm | AZ6: Sea side | BG6: https://cdn.webshopapp.com/shops/298158/files/326410098/file.jpg | FQ6: Artisanal
A7: Decoration/Wall decoration/Decorative plates | B7: BA002W-L | C7: =_xlfn.XLOOKUP(B7,Sheet1!A:A,Sheet1!A:A,) -> BA002W-L | D7: A croix de la coquille blanc | E7: La concha cruz blanca | F7: Croce di conchiglia bianca | G7: Weißes Muschelkreuz | H7: 7438246080013 | J7: Bazar Bizar | L7: <p>Ces belles croix décoratives côtières sont recouvertes de coquillages blancs qui composent un joli motif floral. Elles sont superbes suspendues ou posées sur une table ou une étagère. Un joli must de la décoration côtière !</p> | M7: <p>Queste belle croci decorative stile costiere, sono coperte di conchiglie bianche che formano un bel motivo floreale. Stanno benissimo appese o appoggiate su un tavolo o una mensola. Una bella must-have decorazione boho!</p> | N7: <p>Estas bonitas cruces costeras decorativas están cubiertas de conchas blancas, formando un bonito diseño de flores. Quedan muy bien colgadas o colocadas sobre una mesa o estantería. ¡Una preciosa adición a tu decoración costera!</p> | O7: <p>Diese schönen dekorativen Küstenkreuze sind mit weißen Muscheln bedeckt, die ein hübsches Muster bilden. Sie sehen toll aus, wenn man sie aufhängt oder auf einen Tisch oder ein Regal legt. Eine schöne Küstendekoration, die man einfach haben muss!</p> | P7: White | Q7: Mother-of-pear | R7: Coquille | S7: Concha | T7: Schale | U7: Conchiglia | V7: White | W7: White | X7: White | Y7: White | Z7: 4 | AA7: cm | AB7: 32 | AC7: cm | AD7: 43 | AE7: cm | AG7: cm | AT7: Indonesia | AZ7: Sea side | BG7: https://bazarbizar.katanapim.com/content/images/thumbs/001/0013971_the-shell-cross-white-l.jpeg | CD7: 32cm x 43cm x 4cm | CG7: https://bazarbizar.katanapim.com/content/images/thumbs/001/0013972_the-shell-cross-white-l.jpeg | CJ7: https://bazarbizar.katanapim.com/content/images/thumbs/001/0013973_the-shell-cross-white-l.jpeg | EX7: Sea
A8: Decoration/Wall decoration/Decorative plates | B8: BA002W-M | C8: =_xlfn.XLOOKUP(B8,Sheet1!A:A,Sheet1!A:A,) -> BA002W-M | D8: Croix suspendue en coquillages blanc | E8: Cruz colgante de conchas | F8: Croce appesa in conchiglie bianche | H8: 7438246080006 | L8: Ces belles croix décoratives côtières sont recouvertes de coquillages blancs qui composent un joli motif floral. Elles sont superbes suspendues ou posées sur une table ou une étagère. Un joli must de la décoration côtière ! | N8: Estas bonitas cruces recubiertas de conchas blancas, forman un bonito diseño en forma de flor. Son el perfecto elemento decorativo de estilo costero, que queda muy bien colgada, encima de una mesa o sobre una estantería. ¡No te quedes sin la tuya! | P8: White | Z8: 31 | AA8: cm | AC8: cm | AE8: cm | BG8: https://cdn.webshopapp.com/shops/298158/files/454900699/file.jpg
A9: Decoration/Wall decoration/Decorative plates | B9: BA005W-M | C9: =_xlfn.XLOOKUP(B9,Sheet1!A:A,Sheet1!A:A,) -> BA005W-M | D9: Coeur suspendu en coquillages | E9: Corazón colgante de conchas | F9: Cuore appeso in conchiglie bianche | H9: 7438246079086 | J9: Bazar Bizar | L9: Ces magnifiques cœurs décoratifs côtiers sont recouverts de coquillages blancs qui composent un joli motif floral. Ils sont superbes suspendus ou posés sur une table ou une étagère. Un joli must de la décoration côtière ! | M9: Questa bella croce decorativa costiera è ricoperta di conchiglie bianche, creando un bel motivo. Può essere appeso al muro o su un tavolo o una mensola - una bella decorazione costiera must-have! | N9: Estos bonitos corazones recubiertos de conchas blancas, forman un bonito diseño en forma de flor. Son el perfecto elemento decorativo de estilo costero, que queda muy bien colgado, encima de una mesa o sobre una estantería. ¡No te quedes sin el tuyo! | O9: Diese schönen dekorativen Küstenherzen sind mit weißen Muscheln bedeckt, die ein hübsches Blumenmuster bilden. Sie sehen toll aus, wenn man sie aufhängt oder auf einen Tisch oder ein Regal legt. Eine schöne Küstendekoration, die man einfach haben muss! | P9: White | Q9: Natural fibers | AA9: cm | AB9: 17 | AC9: cm | AD9: 17 | AE9: cm | BG9: https://cdn.webshopapp.com/shops/298158/files/426857694/file.jpg | BH9: https://cdn.webshopapp.com/shops/298158/files/430889573/file.jpg | CG9: https://cdn.webshopapp.com/shops/298158/files/430889465/file.jpg | CJ9: https://cdn.webshopapp.com/shops/298158/files/430889567/file.jpg | CM9: https://cdn.webshopapp.com/shops/298158/files/432095718/file.jpg
A10: Lifestyle/Pockets and wallets/Purses and wallets | B10: BA017Br | C10: =_xlfn.XLOOKUP(B10,Sheet1!A:A,Sheet1!A:A,) -> BA017Br | H10: 7438246176174 | J10: Bazar Bizar | L10: <p>Un équilibre délicat entre texture et fonction définit la Pochette Purse en Cuir, conçue pour accompagner des moments qui traversent la journée avec fluidité. Dans cette composition apaisée, cette petite pochette en cuir marron s’intègre naturellement aux routines détendues et offre une présence discrète.</p> <p>Au delà de sa taille, l’expérience se révèle à l’usage. Portée à la main ou glissée sous le bras, elle accompagne les déplacements lents à travers marchés, dîners ou soirées improvisées. La façade tissée apporte de la profondeur tandis que le dos en cuir lisse repose confortablement contre le corps, créant un dialogue subtil entre matière et toucher.</p> <p>Fabriquée en Indonésie, cette pochette en cuir faite main associe cuir et coquillage selon des techniques traditionnelles. De légères variations de ton et de tissage reflètent l’origine des matériaux et confèrent à chaque pochette un caractère façonné par le lieu et le geste.</p> | M10: <p>Un delicato equilibrio tra texture e funzione definisce la Borsa Purse in Pelle, pensata per accompagnare momenti che scorrono con naturalezza durante la giornata. In questa composizione calma, questa piccola borsa in pelle marrone si inserisce spontaneamente nelle routine rilassate offrendo una presenza discreta.</p> <p>Oltre alle dimensioni, l’esperienza emerge nell’uso. Portata a mano o sotto il braccio, accompagna movimenti lenti tra mercati, cene o serate senza programma. Il pannello intrecciato frontale aggiunge profondità, mentre il retro in pelle liscia aderisce comodamente al corpo, creando un dialogo silenzioso tra materiale e tatto.</p> <p>Realizzata in Indonesia, questa borsa in pelle artigianale unisce pelle e conchiglia attraverso tecniche tradizionali. Le leggere variazioni di tono e intreccio riflettono l’origine dei materiali e conferiscono a ogni clutch un carattere plasmato dal luogo e dal processo.</p> | N10: <p>Existe un equilibrio suave entre textura y función en el Bolso Purse de Cuero, creado para acompañar momentos que fluyen a lo largo del día. En esta composición serena, este pequeño bolso de cuero marrón se integra de forma natural en rutinas relajadas y ofrece presencia sin imponerse.</p> <p>Más allá del tamaño, la experiencia reside en el uso. Llevado en la mano o bajo el brazo, acompaña movimientos tranquilos por mercados, cenas o noches improvisadas. El frontal tejido aporta profundidad, mientras que la parte trasera de cuero liso descansa cómodamente contra el cuerpo, creando un ritmo discreto entre material y tacto.</p> <p>Elaborado en Indonesia, este bolso de cuero hecho a mano combina cuero y concha mediante técnicas tradicionales. Sutiles variaciones de tono y trama reflejan el origen del material y otorgan a cada bolso tipo clutch un carácter definido por el lugar y el proceso.</p> | O10: <p>Ein sanftes Gleichgewicht zwischen Textur und Funktion prägt die Purse Leder Tasche, gestaltet für Momente, die sich leicht durch den Tag bewegen. In dieser ruhigen Komposition fügt sich diese kleine braune Ledertasche natürlich in entspannte Routinen ein und zeigt Präsenz ohne Aufmerksamkeit zu verlangen.</p> <p>Über die Größe hinaus liegt das Erlebnis in der Nutzung. In der Hand gehalten oder unter dem Arm getragen begleitet sie ruhige Wege über Märkte, zu Abendessen oder durch ungeplante Abende. Die gewebte Vorderseite verleiht Tiefe, während die glatte Lederseite angenehm am Körper anliegt und einen leisen Rhythmus zwischen Material und Berührung schafft.</p> <p>In Indonesien gefertigt vereint diese handgearbeitete Ledertasche Leder und Muschel mit traditionellen Techniken. Feine Variationen in Ton und Flechtung spiegeln die Materialherkunft wider und verleihen jeder Leder Clutch einen Charakter, der von Ort und Prozess geprägt ist.</p> | P10: Brown | Q10: Leather split leather | Z10: 1 | AA10: cm | AB10: 20 | AC10: cm | AD10: 14 | AE10: cm | AG10: cm | AT10: Indonesia | BG10: https://bazarbizar.katanapim.com/content/images/thumbs/001/0016178_the-purse-leather-purse-brown.jpeg | CA10: Bazar Bizar | CB10: 2550 | CD10: 20 x 14 x 1 cm
A11: Decoration/Decoration objects/Indoor pots | B11: BA024NB-M | C11: =_xlfn.XLOOKUP(B11,Sheet1!A:A,Sheet1!A:A,) -> BA024NB-M | H11: 7438246095048 | J11: Bazar Bizar | K11: Cowrie | Z11: 15 | AA11: cm | AB11: 17 | AC11: cm | AD11: 17 | AE11: cm
A12: Decoration/Decoration objects/Vases | B12: BA024N-M | C12: =_xlfn.XLOOKUP(B12,Sheet1!A:A,Sheet1!A:A,) -> BA024N-M | D12: Porte-plante en coton et coquillage blanc | E12: Jardinera de algodón y concha blanca | F12: Portapiante in cotone e conchiglia bianca | H12: 7438246094041 | J12: Bazar Bizar | L12: Vous pouvez habiller vos vieux et laids pots, vases ou planteurs avec nos planteurs au crochet et les rendre tout stylé et conçu vers le haut.Soit il est sur votre table d'appoint, étagère manteau ou dans la salle de bains les planteurs enveloppés dans ces belles couvertures de crochet serait ajouter plus de lunes de beauté à votre décor et le style de la maison. Ces magnifiques couvertures sont le cadeau parfait pour vos proches. | M12: Ora puoi vestire i tuoi vecchi vasi da fiori, vasi o fioriere con i nostri portavasi all'uncinetto e farli sembrare eleganti e disegnati. Sul tavolino, sulla mensola del camino o in bagno, i vasi avvolti in queste belle coperture all'uncinetto aggiungeranno un tocco di stile alla vostra casa. Queste belle copertine sono il regalo perfetto per i vostri cari! | N12: Ahora puedes vestir a tus viejas macetas, jarrones o jardineras con nuestros maceteros de macramé y hacer que se vean mucho más estilizadas y bonitas. Utilízalas en una mesita de noche, en la repisa de la chimenea o en un baño, y observa como agregan belleza a la decoración y al estilo de tu hogar. ¡También hacen el regalo perfecto para tus seres queridos! | P12: Beige | Q12: Cotton | Z12: 15 | AA12: cm | AB12: 17 | AC12: cm | AD12: 17 | AE12: cm | BG12: https://cdn.webshopapp.com/shops/298158/files/456721664/file.jpg
A13: Decoration/Decoration objects/Vases | B13: BA025W-M | C13: =_xlfn.XLOOKUP(B13,Sheet1!A:A,Sheet1!A:A,) -> BA025W-M | H13: 7438246080099 | J13: Bazar Bizar | Z13: 14 | AA13: cm | AB13: 17 | AC13: cm | AD13: 17 | AE13: cm | BG13: https://cdn.webshopapp.com/shops/298158/files/426857738/file.jpg
A14: Decoration/Candles and fragrance/Candles/Candle | B14: BA025W-S | C14: =_xlfn.XLOOKUP(B14,Sheet1!A:A,Sheet1!A:A,) -> BA025W-S | H14: 7438246080082 | J14: Bazar Bizar | Z14: 8 | AA14: cm | AB14: 12 | AC14: cm | AD14: 12 | AE14: cm | BG14: https://cdn.webshopapp.com/shops/298158/files/426857719/file.jpg
A15: Storage accessories/Decorative storages/Baskets | B15: BA028N-SET2 | C15: =_xlfn.XLOOKUP(B15,Sheet1!A:A,Sheet1!A:A,) -> BA028N-SET2 | D15: Panier en perles et noix de coco naturel set de 2 | E15: Cesta de cuentas y coco juego de 2 | F15: Set di 2 cestini di perline e cocco | G15: 2er Set Korb aus coconut und muscheln | H15: 7438246090005 | J15: Bazar Bizar | L15: <p>Le panier carré en coquille de noix de coco est utilisé à l'origine comme boîte à offrandes, entièrement fabriqué à la main par des artisans balinais avec amour et soin. Fabriqué à partir de noix de coco et de bambou. Elles sont utilisées à Bali lors des cérémonies religieuses pour contenir les offrandes aux dieux, transformées en objet décoratif ces boîtes ajouteront une touche d'authenticité et d'exotisme à votre décoration. Posez-les sur une étagère pour attirer le regard dans votre salle de bain, votre chambre à coucher ou votre chambre d'enfant. Parfaites pour ranger vos bijoux ou de plus petits objets précieux que vous ne voulez jamais perdre. Un beau cadeau pour un être cher!</p> | M15: <p>Il Cestino Quadrato in Conchiglia di Cocco è originariamente usato come Scatola delle Offerte, interamente fatto a mano da artigiani balinesi con amore e cura. È stato usato a Bali durante le cerimonie religiose per fare offerte agli dei. Ora potete avere questo elemento bello ed esotico nella tua casa, aggiungerà molto stile alla tua decorazione!</p> | N15: <p>La cesta de cáscara de coco fue creada originalmente como caja de ofrendas, está hecha a mano con coco y bambú por artesanos balineses. Se usa en las ceremonias religiosas para guardar ofrendas a los dioses, pero ahora han sido convertidas en un elegante elemento decorativo que añadirá un toque de autenticidad y exotismo a tu decoración. Colócalas en una estantería, un cuarto de baño, dormitorio o también en la habitación de los niños. Son perfectas para guardar joyas u objetos pequeños que no quisieras perder de vista. ¡Hacen también un bonito regalo para un ser querido!</p> | O15: <p>Der quadratische Korb aus Kokosnussschalen wurde ursprünglich als Opfergabe verwendet und wird von balinesischen Kunsthandwerkern mit viel Liebe und Sorgfalt handgefertigt. Hergestellt aus Kokosnuss und Bambus. Sie werden in Bali bei religiösen Zeremonien verwendet, um Opfergaben für die Götter aufzubewahren. Umgewandelt in ein dekoratives Objekt verleihen diese Boxen Ihrer Dekoration einen Hauch von Authentizität und Exotik. Stellen Sie sie auf ein Regal als Blickfang in Ihrem Badezimmer, Schlafzimmer oder Kinderzimmer. Perfekt für die Aufbewahrung von Schmuck oder kleineren Kostbarkeiten, die Sie nie verlieren möchten. Ein schönes Geschenk für einen geliebten Menschen!</p> | P15: Beige | Q15: Bamboo | R15: Bambou - Coco | S15: Bambú - Coco | T15: Bamboo - Kokosnuss | U15: Bambù - Cocco | V15: Naturel | W15: Natural | X15: Naturale | Y15: Natur | Z15: 13 - 14 | AA15: cm | AB15: 20 - 28 | AC15: cm | AD15: 20 - 28 | AE15: cm | AG15: cm | AT15: Indonesia | AZ15: Sea side | BG15: https://bazarbizar.katanapim.com/content/images/thumbs/0009596_ba028n-set2.webp | BH15: https://bazarbizar.katanapim.com/content/images/thumbs/0009605_ba028n-set2_109.webp | BI15: https://bazarbizar.katanapim.com/content/images/thumbs/0009598_ba028n-set2_102.webp | BJ15: https://bazarbizar.katanapim.com/content/images/thumbs/0012435_ba028n-set2_3.webp | BK15: https://bazarbizar.katanapim.com/content/images/thumbs/0012292_ba028n-set2_4.webp | CD15: 20 - 28cm x 20 - 28cm x 13 - 14cm | CG15: https://bazarbizar.katanapim.com/content/images/thumbs/0014530_the-coconut-shell-basket-natural-set-of-2.webp | CJ15: https://bazarbizar.katanapim.com/content/images/thumbs/0009601_ba028n-set2_105.webp | CM15: https://bazarbizar.katanapim.com/content/images/thumbs/0014529_the-simba-mirror-black-l.webp | FQ15: Artisanal
A16: Lifestyle/Bags/Tote bags | B16: BA032BB-L | C16: =_xlfn.XLOOKUP(B16,Sheet1!A:A,Sheet1!A:A,) -> BA032BB-L | D16: Pochette en raphia noir | E16: Clutch de rafia negro | F16: Pochette in rafia nero 32x3 cm | G16: Reissverschluss aus Bast schwarz | H16: 7438246082000 | I16: BA032 | J16: Bazar Bizar | K16: Raffia | L16: Ajoutez une touche d'lgance votre tenue avec notre Pochette en raphia noir. Fabrique partir de raphia de haute qualit, cette pochette spacieuse dgage sophistication et style. Son design pur et sa couleur noire intemporelle en font l'accessoire parfait pour toutes les occasions, que ce soit une sortie dcontracte ou un vnement spcial en soire. | M16: Aggiungi un tocco di eleganza al tuo outfit con la nostra Clutch in Rafia Nera. Realizzata in rafia di alta qualit, questa clutch spaziosa emana sofisticazione e stile. Il suo design sobrio e il colore nero senza tempo la rendono l'accessorio perfetto per ogni occasione, che sia una gita informale o un evento serale speciale. | N16: Agrega un toque de elegancia a tu conjunto con nuestro Clutch de Rafia en Negro. Confeccionado con rafia de alta calidad, este clutch espacioso irradia sofisticación y estilo. Su o estilizado y su color negro atemporal lo convierten en el accesorio perfecto para cualquier ocasión, ya sea una salida casual o un evento especial por la noche. | O16: Verleihen Sie Ihrem Outfit mit unserer Raffia Clutch in Schwarz eine elegante Note. Hergestellt aus hochwertigem Raffia, strahlt diese geräumige Clutch Raffinesse und Stil aus. Ihr schlankes Design und die zeitlose schwarze Farbe machen sie zum perfekten Accessoire jeden Anlass, ob es sich um einen zwanglosen Ausflug oder ein besonderes Abendevent handelt. | P16: Black | Q16: Natural fibers | R16: Raphia | S16: Rafia | T16: Bast | U16: Rafia | Z16: 20 | AA16: cm | AB16: 32 | AC16: cm | AD16: 3 | AE16: cm | AG16: cm | AT16: Indonesia | BG16: https://bazarbizar.katanapim.com/content/images/thumbs/000/0000368_ba032bb-l.jpeg | CA16: Bazar Bizar | CB16: 2550 | CD16: 32 x 3 x 20 cm | CG16: https://bazarbizar.katanapim.com/content/images/thumbs/002/0023005_the-raffia-clutch-black-l.jpeg | DD16: Without pattern
A17: Lifestyle/Bags/Tote bags | B17: BA032BB-S | C17: =_xlfn.XLOOKUP(B17,Sheet1!A:A,Sheet1!A:A,) -> BA032BB-S | D17: Pochette en raphia noir | E17: Embrague de rafia negro | F17: Pochette in rafia nero | G17: Reissverschluss aus Bast schwarz | H17: 7438246082017 | I17: BA032 | J17: Bazar Bizar | L17: <p><span>Ajoutez une touche d'élégance à votre tenue avec notre Pochette en raphia noir. Fabriquée à partir de raphia de haute qualité, cette pochette compacte dégage sophistication et style. Son design épuré et sa couleur noire intemporelle en font l'accessoire parfait pour toutes les occasions, que ce soit une sortie décontractée ou un événement spécial en soirée.</span></p> | M17: <p><span>Aggiungi un tocco di eleganza al tuo outfit con la nostra Clutch in Rafia Nera. Realizzata in rafia di alta qualità, questa clutch compatta emana sofisticazione e stile. Il suo design sobrio e il colore nero senza tempo la rendono l'accessorio perfetto per ogni occasione, che sia una gita informale o un evento serale speciale.</span></p> | N17: <p><span>Agrega un toque de elegancia a tu conjunto con nuestro Clutch de Rafia en Negro. Confeccionado con rafia de alta calidad, este clutch compacto irradia sofisticación y estilo. Su diseño estilizado y su color negro atemporal lo convierten en el accesorio perfecto para cualquier ocasión, ya sea una salida casual o un evento especial por la noche.</span></p> | O17: <p><span>Verleihen Sie Ihrem Outfit mit unserer Raffia Clutch in Schwarz eine elegante Note. Hergestellt aus hochwertigem Raffia, strahlt diese kompakte Clutch Raffinesse und Stil aus. Ihr schlankes Design und die zeitlose schwarze Farbe machen sie zum perfekten Accessoire für jeden Anlass, ob es sich um einen zwanglosen Ausflug oder ein besonderes Abendevent handelt.</span></p> | P17: Black | R17: Raphia | S17: Rafia | T17: Raffia | U17: Rafia | V17: Noir | W17: Negro | X17: Nero | Y17: Schwarz | Z17: 15 | AA17: cm | AB17: 25 | AC17: cm | AD17: 3 | AE17: cm | AG17: cm | AT17: Indonesia | AZ17: Sea side | BG17: https://bazarbizar.katanapim.com/content/images/thumbs/0000369_ba032bb-s.jpeg | CD17: 25cm x 3cm x 15cm | CG17: https://bazarbizar.katanapim.com/content/images/thumbs/0009619_ba032bb-s_401.webp | CJ17: https://bazarbizar.katanapim.com/content/images/thumbs/0009618_ba032bb-s_400.webp | CM17: https://bazarbizar.katanapim.com/content/images/thumbs/0009620_ba032bb-s_402.webp | DD17: Without pattern
A18: Lifestyle/Bags/Tote bags | B18: BA032NB-L | C18: =_xlfn.XLOOKUP(B18,Sheet1!A:A,Sheet1!A:A,) -> BA032NB-L | D18: Pochette en raphia noir naturel | E18: Embrague de rafia natur negro | F18: Pochette in rafia naturale nero | G18: Reissverschluss aus Bast natur schwarz | H18: 7438246082024 | I18: BA032 | J18: Bazar Bizar | L18: <p><span>Rehaussez votre style de vie côtier avec notre Pochette en raphia naturel noir. Fabriquée à partir de raphia de haute qualité avec des accents noirs, cette pochette mêle élégance naturelle et charme côtier, incarnant l'essence de la sophistication en bord de mer. </span></p> <p><span>Son design épuré et sa combinaison de couleurs intemporelle en font l'accessoire parfait pour toutes les occasions, que ce soit une journée décontractée ou une soirée glamour.</span></p> | M18: <p><span>Eleva il tuo stile di vita costiero con la nostra Clutch in Rafia Naturale Nera. Realizzata in rafia di alta qualità con accenti neri, questa clutch fonde eleganza naturale con il fascino della costa, incarnando l'essenza della sofisticazione marittima. </span></p> <p><span>Il suo design sobrio e la combinazione di colori senza tempo la rendono l'accessorio perfetto per ogni occasione, che sia una giornata casual o una serata glamour.</span></p> | N18: <p><span>Eleva tu estilo de vida costero con nuestro Clutch de Rafia en Negro Natural. Confeccionado con rafia de alta calidad con acentos negros, este clutch combina elegancia natural con el encanto costero, encarnando la esencia de la sofisticación junto al mar. </span></p> <p><span>Su diseño estilizado y su combinación de colores atemporal lo convierten en el accesorio perfecto para cualquier ocasión, ya sea un día casual o una velada glamorosa.</span></p> | O18: <p><span>Verleihen Sie Ihrem Küstenlebensstil mit unserer Raffia Clutch in Natur Schwarz eine besondere Note. Hergestellt aus hochwertigem Raffia mit schwarzen Akzenten, vereint diese Clutch natürliche Eleganz mit dem Charme der Küste und verkörpert so die Essenz der Küstensophistication. </span></p> <p><span>Ihr schlankes Design und die zeitlose Farbkombination machen sie zum perfekten Accessoire für jeden Anlass, ob ein lässiger Tag oder ein glamouröser Abend.</span></p> | P18: Multicolour | R18: Raphia | S18: Rafia | T18: Raffia | U18: Rafia | V18: Naturel Noir | W18: Natural Negro | X18: Naturale Nero | Y18: Natur Schwarz | Z18: 20 | AA18: cm | AB18: 32 | AC18: cm | AD18: 3 | AE18: cm | AG18: cm | AT18: Indonesia | AZ18: Sea side | BG18: https://bazarbizar.katanapim.com/content/images/thumbs/0000370_ba032nb-l.jpeg | CD18: 32cm x 3cm x 20cm | CG18: https://bazarbizar.katanapim.com/content/images/thumbs/0009623_ba032nb-l_302.webp | CJ18: https://bazarbizar.katanapim.com/content/images/thumbs/0009627_ba032nb-l_306.webp | CM18: https://bazarbizar.katanapim.com/content/images/thumbs/0009624_ba032nb-l_303.webp | DD18: Without pattern
A19: Lifestyle/Bags/Tote bags | B19: BA032NB-S | C19: =_xlfn.XLOOKUP(B19,Sheet1!A:A,Sheet1!A:A,) -> BA032NB-S | H19: 7438246082031 | I19: BA032 | J19: Bazar Bizar | L19: <p><span>Rehaussez votre style de vie côtier avec notre Pochette en raphia naturel noir. Fabriquée à partir de raphia de haute qualité avec des accents noirs, cette pochette mêle élégance naturelle et charme côtier, incarnant l'essence de la sophistication en bord de mer. </span></p> <p><span>Son design épuré et sa combinaison de couleurs intemporelle en font l'accessoire parfait pour toutes les occasions, que ce soit une journée décontractée ou une soirée glamour.</span></p> | M19: <p><span>Eleva il tuo stile di vita costiero con la nostra Clutch in Rafia Naturale Nera. Realizzata in rafia di alta qualità con accenti neri, questa clutch fonde eleganza naturale con il fascino della costa, incarnando l'essenza della sofisticazione marittima. </span></p> <p><span>Il suo design sobrio e la combinazione di colori senza tempo la rendono l'accessorio perfetto per ogni occasione, che sia una giornata casual o una serata glamour.</span></p> | N19: <p><span>Eleva tu estilo de vida costero con nuestro Clutch de Rafia en Negro Natural. Confeccionado con rafia de alta calidad con acentos negros, este clutch combina elegancia natural con el encanto costero, encarnando la esencia de la sofisticación junto al mar. </span></p> <p><span>Su diseño estilizado y su combinación de colores atemporal lo convierten en el accesorio perfecto para cualquier ocasión, ya sea un día casual o una velada glamorosa.</span></p> | O19: <p>Verleihen Sie Ihrem Küstenlebensstil mit unserer Raffia Clutch in Natur Schwarz eine besondere Note. Hergestellt aus hochwertigem Raffia mit schwarzen Akzenten, vereint diese Clutch natürliche Eleganz mit dem Charme der Küste und verkörpert so die Essenz der Küstensophistication.</p> <p>Ihr schlankes Design und die zeitlose Farbkombination machen sie zum perfekten Accessoire für jeden Anlass, ob ein lässiger Tag oder ein glamouröser Abend.</p> | P19: Multicolour | R19: Raphia | S19: Rafia | T19: Raffia | U19: Rafia | V19: Naturel Noir | W19: Natural Negro | X19: Naturale Nero | Y19: Natur Schwarz | Z19: 15 | AA19: cm | AB19: 25 | AC19: cm | AD19: 3 | AE19: cm | AG19: cm | AT19: Indonesia | AZ19: Sea side | BG19: https://bazarbizar.katanapim.com/content/images/thumbs/0003395_ba032nb-s.webp | CD19: 25cm x 3cm x 15cm | CG19: https://bazarbizar.katanapim.com/content/images/thumbs/0013870_the-raffia-clutch-natural-black-s.jpeg | CJ19: https://bazarbizar.katanapim.com/content/images/thumbs/0013871_the-raffia-clutch-natural-black-s.jpeg | DD19: Without pattern
A20: Home textiles/Soft furnishings/Cushions and covers/Cushions | B20: BA035N-L-60x60 | C20: =_xlfn.XLOOKUP(B20,Sheet1!A:A,Sheet1!A:A,) -> BA035N-L-60x60 | H20: 7438246082055 | J20: Bazar Bizar | Z20: 10 | AA20: cm | AB20: 60 | AC20: cm | AD20: 60 | AE20: cm | BG20: https://cdn.webshopapp.com/shops/298158/files/426858122/file.jpg | BH20: https://cdn.webshopapp.com/shops/298158/files/426858111/file.jpg | CG20: https://cdn.webshopapp.com/shops/298158/files/329151415/file.jpg | CJ20: https://cdn.webshopapp.com/shops/298158/files/345210143/file.jpg | CM20: https://cdn.webshopapp.com/shops/298158/files/329151451/file.jpg
A21: Home textiles/Soft furnishings/Cushions and covers/Cushions | B21: BA035N-M-40x40 | C21: =_xlfn.XLOOKUP(B21,Sheet1!A:A,Sheet1!A:A,) -> BA035N-M-40x40 | H21: 7438246096007 | J21: Bazar Bizar | Z21: 10 | AA21: cm | AB21: 40 | AC21: cm | AD21: 40 | AE21: cm | BG21: https://cdn.webshopapp.com/shops/298158/files/426858103/file.jpg
A22: Decoration/Decoration objects/Busts and statues | B22: BA068S-S | C22: =_xlfn.XLOOKUP(B22,Sheet1!A:A,Sheet1!A:A,) -> BA068S-S | H22: 7438246171117 | J22: Bazar Bizar | L22: 0 | M22: 0 | N22: 0 | O22: 0 | P22: Silver | Q22: Resin | Z22: 7 | AA22: cm | AB22: 7 | AC22: cm | AD22: 9 | AE22: cm | AG22: cm | AT22: Indonesia | BG22: https://bazarbizar.katanapim.com/content/images/thumbs/001/0016152_the-mexican-sugar-skull-silver-s.jpeg | CA22: Bazar Bizar | CB22: 2550 | CD22: 7 x 9 x 7 cm | EX22: Sea
A23: Storage accessories/Utilitarian storages/Utilitarian boxes | B23: BA072BG-L | C23: =_xlfn.XLOOKUP(B23,Sheet1!A:A,Sheet1!A:A,) -> BA072BG-L | H23: 7438246276232 | J23: Bazar Bizar | K23: Beaded | Z23: 15 | AA23: cm | AB23: 20 | AC23: cm | AD23: 20 | AE23: cm
A24: Storage accessories/Utilitarian storages/Utilitarian boxes | B24: BA072BG-M | C24: =_xlfn.XLOOKUP(B24,Sheet1!A:A,Sheet1!A:A,) -> BA072BG-M | H24: 7438246276225 | J24: Bazar Bizar | K24: Beaded | Z24: 12 | AA24: cm | AB24: 15 | AC24: cm | AD24: 15 | AE24: cm
A25: Storage accessories/Utilitarian storages/Utilitarian boxes | B25: BA072BG-S | C25: =_xlfn.XLOOKUP(B25,Sheet1!A:A,Sheet1!A:A,) -> BA072BG-S | H25: 7438246276218 | J25: Bazar Bizar | K25: Beaded | Z25: 10 | AA25: cm | AB25: 12 | AC25: cm | AD25: 12 | AE25: cm
A26: Storage accessories/Decorative storages/Baskets | B26: BA072BG-SET3 | C26: =_xlfn.XLOOKUP(B26,Sheet1!A:A,Sheet1!A:A,) -> BA072BG-SET3 | H26: 7438246171131 | J26: Bazar Bizar | K26: Diamant
A27: Storage accessories/Decorative storages/Baskets | B27: BA073BG-L | C27: =_xlfn.XLOOKUP(B27,Sheet1!A:A,Sheet1!A:A,) -> BA073BG-L | H27: 7438246094010 | J27: Bazar Bizar | Z27: 30 | AA27: cm | AB27: 25 | AC27: cm | AD27: 25 | AE27: cm | AZ27: Sea side | BG27: https://cdn.webshopapp.com/shops/298158/files/416464275/file.jpg | FQ27: Artisanal
A28: Storage accessories/Decorative storages/Baskets | B28: BA073BG-M | C28: =_xlfn.XLOOKUP(B28,Sheet1!A:A,Sheet1!A:A,) -> BA073BG-M | H28: 7438246094027 | J28: Bazar Bizar | Z28: 25 | AA28: cm | AB28: 20 | AC28: cm | AD28: 20 | AE28: cm | AZ28: Sea side | BG28: https://cdn.webshopapp.com/shops/298158/files/416463848/file.jpg | FQ28: Artisanal
A29: Storage accessories/Utilitarian storages/Utilitarian boxes | B29: BA073BG-S | C29: =_xlfn.XLOOKUP(B29,Sheet1!A:A,Sheet1!A:A,) -> BA073BG-S | H29: 7438246094034 | J29: Bazar Bizar | K29: Beaded | Z29: 20 | AA29: cm | AB29: 15 | AC29: cm | AD29: 15 | AE29: cm
